Workbook

Sheet Cover
B2: MuleSoft → AWS Migration
B3: Total Cost of Ownership & Return on Investment Analysis
B4: CLIENT-READY ANALYSIS TOOL
B6: KEY METRICS AT A GLANCE
B7: Current Annual MuleSoft Cost | D7: Projected Annual AWS Cost | F7: Year 1 Savings
B8: ='2. Dashboard'!B6 -> 1313340 | D8: ='2. Dashboard'!D6 -> 707295.8 | F8: ='2. Dashboard'!F6 -> 606044.2
B10: Total Migration Investment | D10: Payback Period | F10: 5-Year ROI
B11: ='2. Dashboard'!H6 -> 1864150.7 | D11: ='2. Dashboard'!B8 -> 36.911184 | F11: ='2. Dashboard'!F8 -> 0.4132772
B13: ANNUAL COST BREAKDOWN — YEAR 1 (PLATFORM vs DEVELOPERS)
C14: Platform & Infrastructure | D14: Developers | E14: Total
B15: MuleSoft | C15: ='2. Dashboard'!D18 -> 661440 | D15: ='2. Dashboard'!D19 -> 651900 | E15: ='2. Dashboard'!D20 -> 1313340
B16: AWS | C16: ='2. Dashboard'!D22 -> 11545.798 | D16: ='2. Dashboard'!D23 -> 695750 | E16: ='2. Dashboard'!D24 -> 707295.8
B20: HOW TO USE THIS CALCULATOR
B21: 1. Open the '1. Configure' sheet and fill in your organization's actual data (all blue cells are editable).
B22: 2. Start with the 'Typical Range' values as a baseline, then refine with your real numbers.
B23: 3. Switch to the '2. Dashboard' sheet to see the auto-calculated TCO comparison, ROI, and charts.
B24: 4. Adjust any input and the entire analysis updates automatically — all sheets are formula-linked.
B27: SHEET NAVIGATION
B28: Sheet | C28: What You'll Find There
B29: 1. Configure | C29: All editable inputs: your current MuleSoft deployment, AWS target architecture, migration scope, unit costs, and financial assumptions.
B30: 2. Dashboard | C30: Complete results: 5-year TCO comparison, migration investment breakdown, ROI analysis, payback period, cumulative savings, and three charts.
B33: All calculations are formula-linked and update automatically when you change any input in the Configure sheet.
B34: Prepared using standard AWS pricing and industry benchmarks. Actual results will vary based on your specific architecture and negotiation outcomes.

Sheet 1. Configure
C2: MuleSoft → AWS Migration
C3: Configure your migration parameters. All blue cells are editable. Everything else auto-calculates.
C5: Parameter | D5: Your Value | E5: Unit | F5: Description | G5: Typical Range | H5: Source
C7: A. CURRENT MULESOFT DEPLOYMENT
C8: Production vCores | D8: 4 | E8: vCores | F8: MuleSoft runtime vCores in Production. Each vCore = 1 vCPU + 2 GB RAM. | G8: 4–16 vCores for mid-market | H8: Anypoint Runtime Manager
C9: Non-Production vCores | D9: 2 | E9: vCores | F9: Dev, QA, Staging, and UAT environments. Typically 30–50% of prod. | G9: 2–8 vCores | H9: Include sandbox environments
C10: Platform Tier | D10: Platinum | E10: Tier | F10: Subscription tier: Gold ($75K/yr), Platinum ($150K/yr), Titanium ($300K/yr). | G10: Platinum is most common | H10: Current contract
C11: Annual Platform Subscription | D11: 150000 | E11: USD/yr | F11: Base platform fee before vCores and connectors. Billed annually. | G11: $75K–$300K depending on tier | H11: Salesforce invoice
C12: Premium Connectors (count) | D12: 1 | E12: connectors | F12: Licensed connectors: SAP, Oracle, Workday, Salesforce, NetSuite, etc. | G12: 0–10 typical | H12: Anypoint Exchange
C13: Cost per Premium Connector | D13: 12000 | E13: USD/yr | F13: Annual license cost per premium connector. | G13: $10K–$15K each | H13: Salesforce quote
C14: Anypoint MQ (monthly) | D14: 2000 | E14: USD/mo | F14: Managed messaging queue costs. Charged by message volume and storage. | G14: $500–$5,000/mo | H14: Anypoint MQ dashboard
C15: Dedicated Load Balancers | D15: 1 | E15: DLBs | F15: Number of DLBs for custom TLS domains and static IPs. | G15: 1–3 typical | H15: Network architecture
C16: Cost per DLB (monthly) | D16: 4000 | E16: USD/mo | F16: Monthly cost per DLB. Includes SSL termination and static IP. | G16: $3,000–$5,000 each | H16: Salesforce pricing
C17: Annual Support & Maintenance | D17: 100000 | E17: USD/yr | F17: Premier support, success plans, or extended support hours. | G17: $50K–$100K/yr | H17: Support contract
C18: MuleSoft Developers (FTE) | D18: 4 | E18: FTEs | F18: Full-time employees dedicated to MuleSoft development and ops. | G18: 3–8 for mid-market | H18: HR / org chart
C19: Avg MuleSoft Developer Salary | D19: 150000 | E19: USD/yr | F19: Fully-loaded annual salary per MuleSoft developer. | G19: $150K–$180K | H19: Compensation data
C20: Annual Training & Certification | D20: 15000 | E20: USD/yr | F20: MuleSoft certifications and conference attendance. | G20: $10K–$20K/yr | H20: Training budget
C21: Contract Annual Escalation | D21: 0.06 | E21: Percent | F21: Year-over-year price increase in MuleSoft contract. | G21: 5% to 8% | H21: Contract terms
C23: B. AWS TARGET ARCHITECTURE & USAGE
C24: Monthly API Requests | D24: 50 | E24: millions/mo | F24: Total API calls hitting API Gateway per month. | G24: 20–100M for mid-market | H24: Current API gateway metrics
C25: API Gateway Type | D25: HTTP | E25: Type | F25: HTTP API ($1/M req) is cheaper than REST ($3.50/M req). | G25: HTTP: $1/M | REST: $3.50/M | H25: Architecture decision
C26: Lambda Avg Memory | D26: 512 | E26: MB | F26: Average memory allocated per Lambda function. | G26: 256MB–1024MB typical | H26: CloudWatch Logs Insights
C27: Lambda Avg Duration | D27: 200 | E27: ms | F27: Average cold-start + execution time per Lambda. | G27: 100–500ms typical | H27: X-Ray or CloudWatch
C28: Lambda Invocations (monthly) | D28: 50 | E28: millions/mo | F28: Total Lambda executions per month. | G28: 80–95% of API count | H28: CloudWatch metrics
C29: SQS Messages (monthly) | D29: 20 | E29: millions/mo | F29: Amazon SQS messages sent/received. | G29: 10–50M typical | H29: Messaging architecture
C30: EventBridge Events (monthly) | D30: 10 | E30: millions/mo | F30: EventBridge events published and consumed. | G30: 5–20M typical | H30: Event-driven design
C31: Step Functions Transitions (monthly) | D31: 5 | E31: millions/mo | F31: State transitions in Step Functions workflows. | G31: 1–10M typical | H31: Workflow complexity
C32: Fargate vCPU Hours / day | D32: 48 | E32: vCPU-hrs/day | F32: Total vCPU-hours for Fargate containers daily. | G32: 24–96 vCPU-hrs | H32: Container metrics
C33: Fargate Memory GB / day | D33: 96 | E33: GB-hrs/day | F33: Total memory-hours for Fargate containers daily. | G33: 2x vCPU hours typical | H33: Container specs
C34: CloudWatch Logs (monthly) | D34: 500 | E34: GB/mo | F34: Log data ingested into CloudWatch Logs. | G34: 200–1000 GB/mo | H34: Logging strategy
C35: Data Transfer Out (monthly) | D35: 2 | E35: TB/mo | F35: Egress data leaving AWS to external systems. | G35: 1–5 TB typical | H35: Network architecture
C36: AWS Developers (FTE) | D36: 4 | E36: FTEs | F36: Post-migration team size. Often same headcount but lower salary. | G36: 3–6 FTEs | H36: HR planning
C37: Avg AWS Developer Salary | D37: 150000 | E37: USD/yr | F37: Fully-loaded salary for standard integration developers. | G37: $130K–$150K | H37: Market data
... C39: AWS Enterprise Discount | D39: 0.15 | E39: Percent | F39: Volume discount or Reserved Instance savings. | G39: 10% to 20% | H39: AWS account team
C41: C. MIGRATION PROJECT SCOPE
C42: Integrations to Migrate | D42: 10 | E42: count | F42: Total MuleSoft flows, APIs, and integrations in scope. | G42: 15–50 typical | H42: MuleSoft inventory
C43: Complex Integrations (%) | D43: 0.1 | E43: Percent | F43: Share requiring heavy replatforming: SAP/Oracle, multi-step. | G43: 20% to 40% | H43: Architecture review
C44: Medium Integrations (%) | D44: 0.5 | E44: Percent | F44: Standard REST/SOAP flows with moderate business logic. | G44: 40% to 60% | H44: Architecture review
C45: Simple Integrations (%) | D45: 0.4 | E45: Percent | F45: Lightweight pass-through, proxy, or simple routing flows. | G45: 10% to 30% | H45: Architecture review
C46: DataWeave Transformations | D46: 30 | E46: count | F46: Complex DataWeave mappings that must be rewritten. | G46: 20–80 | H46: Code inventory
...

Sheet 2. Dashboard
B2: Executive Dashboard
B3: All values auto-calculated from the Configure sheet. Change inputs there to update this dashboard.
B5: Current Annual MuleSoft Cost | D5: Projected Annual AWS Cost (Y1) | F5: Year 1 Operational Savings | H5: Total Migration Investment
B6: =D20 -> 1313340 | D6: =D24 -> 707295.8 | F6: =D26 -> 606044.2 | H6: =C44 -> 1864150.7
B7: Simple Payback Period | D7: 5-Year NPV of Savings | F7: 5-Year ROI | H7: 5-Year Total Savings
B8: =IF(D26>0,C44/D26*12,0) -> 36.911184 | D8: =NPV('1. Configure'!D65,D26:H26) -> 2131806.6 | F8: =IF(C44>0,(SUM(D26:H26)-C44)/C44,0) -> 0.4132772 | H8: =SUM(D26:H26) -> 2634561.7
B10: ANNUAL COST BREAKDOWN — YEAR 1 (PLATFORM vs DEVELOPERS)
C11: Platform & Infrastructure | D11: Developers | E11: Total
B12: MuleSoft | C12: =D18 -> 661440 | D12: =D19 -> 651900 | E12: =D20 -> 1313340
B13: AWS | C13: =D22 -> 11545.798 | D13: =D23 -> 695750 | E13: =D24 -> 707295.8
B16: 5-YEAR COST COMPARISON: MULESOFT VS AWS
B17: Cost Category | C17: Year 0 | D17: Year 1 | E17: Year 2 | F17: Year 3 | G17: Year 4 | H17: Year 5
B18: MuleSoft — Platform & Infrastructure | C18: 0 | D18: ='1. Configure'!D11*(1+'1. Configure'!D21)^1+'1. Configure'!D8*55000*(1+'1. Configure'!D21)^1+'1. Configure'!D9*35000*(1+'1. Configure'!D21)^1+'1. Configure'!D12*'1. Configure'!D13*(1+'1. Configure'!D21)^1+'1. Configure'!D14*12*(1+'1. Configure'!D21)^1+'1. Configure'!D15*'1. Configure'!D16*12*(1+'1. Configure'!D21)^1+'1. Configure'!D17*(1+'1. Configure'!D21)^1 -> 661440 | E18: ='1. Configure'!D11*(1+'1. Configure'!D21)^2+'1. Configure'!D8*55000*(1+'1. Configure'!D21)^2+'1. Configure'!D9*35000*(1+'1. Configure'!D21)^2+'1. Configure'!D12*'1. Configure'!D13*(1+'1. Configure'!D21)^2+'1. Configure'!D14*12*(1+'1. Configure'!D21)^2+'1. Configure'!D15*'1. Configure'!D16*12*(1+'1. Configure'!D21)^2+'1. Configure'!D17*(1+'1. Configure'!D21)^2 -> 701126.4 | F18: ='1. Configure'!D11*(1+'1. Configure'!D21)^3+'1. Configure'!D8*55000*(1+'1. Configure'!D21)^3+'1. Configure'!D9*35000*(1+'1. Configure'!D21)^3+'1. Configure'!D12*'1. Configure'!D13*(1+'1. Configure'!D21)^3+'1. Configure'!D14*12*(1+'1. Configure'!D21)^3+'1. Configure'!D15*'1. Configure'!D16*12*(1+'1. Configure'!D21)^3+'1. Configure'!D17*(1+'1. Configure'!D21)^3 -> 743193.98 | G18: ='1. Configure'!D11*(1+'1. Configure'!D21)^4+'1. Configure'!D8*55000*(1+'1. Configure'!D21)^4+'1. Configure'!D9*35000*(1+'1. Configure'!D21)^4+'1. Configure'!D12*'1. Configure'!D13*(1+'1. Configure'!D21)^4+'1. Configure'!D14*12*(1+'1. Configure'!D21)^4+'1. Configure'!D15*'1. Configure'!D16*12*(1+'1. Configure'!D21)^4+'1. Configure'!D17*(1+'1. Configure'!D21)^4 -> 787785.62 | H18: ='1. Configure'!D11*(1+'1. Configure'!D21)^5+'1. Configure'!D8*55000*(1+'1. Configure'!D21)^5+'1. Configure'!D9*35000*(1+'1. Configure'!D21)^5+'1. Configure'!D12*'1. Configure'!D13*(1+'1. Configure'!D21)^5+'1. Configure'!D14*12*(1+'1. Configure'!D21)^5+'1. Configure'!D15*'1. Configure'!D16*12*(1+'1. Configure'!D21)^5+'1. Configure'!D17*(1+'1. Configure'!D21)^5 -> 835052.76
B19: MuleSoft — People & Developers | C19: 0 | D19: ='1. Configure'!D18*'1. Configure'!D19*(1+'1. Configure'!D21)^1+'1. Configure'!D20*(1+'1. Configure'!D21)^1 -> 651900 | E19: ='1. Configure'!D18*'1. Configure'!D19*(1+'1. Configure'!D21)^2+'1. Configure'!D20*(1+'1. Configure'!D21)^2 -> 691014 | F19: ='1. Configure'!D18*'1. Configure'!D19*(1+'1. Configure'!D21)^3+'1. Configure'!D20*(1+'1. Configure'!D21)^3 -> 732474.84 | G19: ='1. Configure'!D18*'1. Configure'!D19*(1+'1. Configure'!D21)^4+'1. Configure'!D20*(1+'1. Configure'!D21)^4 -> 776423.33 | H19: ='1. Configure'!D18*'1. Configure'!D19*(1+'1. Configure'!D21)^5+'1. Configure'!D20*(1+'1. Configure'!D21)^5 -> 823008.73
B20: TOTAL MULESOFT COST | C20: =C18+C19 -> 0 | D20: =D18+D19 -> 1313340 | E20: =E18+E19 -> 1392140.4 | F20: =F18+F19 -> 1475668.8 | G20: =G18+G19 -> 1564209 | H20: =H18+H19 -> 1658061.5
B22: AWS — Platform & Infrastructure | C22: 0 | D22: =('1. Configure'!D24*1*12*(1+'1. Configure'!D66)^0+'1. Configure'!D28*0.2*12*(1+'1. Configure'!D66)^0+('1. Configure'!D26/1024)*('1. Configure'!D27/1000)*'1. Configure'!D28*0.0000166667*12*(1+'1. Configure'!D66)^0+'1. Configure'!D29*0.4*12*(1+'1. Configure'!D66)^0+MAX(0,'1. Configure'!D30-1)*1*12*(1+'1. Configure'!D66)^0+'1. Configure'!D31*0.000025*1000000*12*(1+'1. Configure'!D66)^0+'1. Configure'!D32*0.04048*365*(1+'1. Configure'!D66)^0+'1. Configure'!D33*0.04479*365*(1+'1. Configure'!D66)^0+'1. Configure'!D34*0.5*12*(1+'1. Configure'!D66)^0+'1. Configure'!D34*12*0.03*12*(1+'1. Configure'!D66)^0+'1. Configure'!D35*1024*0.09*12*(1+'1. Configure'!D66)^0+5*12*(1+'1. Configure'!D66)^0+(1+'1. Configure'!D66)^0*60+32.4*12*(1+'1. Configure'!D66)^0+(1+'1. Configure'!D66)^0*1000)*(1-'1. Configure'!D39) -> 11545.798 | E22: =('1. Configure'!D24*1*12*(1+'1. Configure'!D66)^1+'1. Configure'!D28*0.2*12*(1+'1. Configure'!D66)^1+('1. Configure'!D26/1024)*('1. Configure'!D27/1000)*'1. Configure'!D28*0.0000166667*12*(1+'1. Configure'!D66)^1+'1. Configure'!D29*0.4*12*(1+'1. Configure'!D66)^1+MAX(0,'1. Configure'!D30-1)*1*12*(1+'1. Configure'!D66)^1+'1. Configure'!D31*0.000025*1000000*12*(1+'1. Configure'!D66)^1+'1. Configure'!D32*0.04048*365*(1+'1. Configure'!D66)^1+'1. Configure'!D33*0.04479*365*(1+'1. Configure'!D66)^1+'1. Configure'!D34*0.5*12*(1+'1. Configure'!D66)^1+'1. Configure'!D34*12*0.03*12*(1+'1. Configure'!D66)^1+'1. Configure'!D35*1024*0.09*12*(1+'1. Configure'!D66)^1+5*12*(1+'1. Configure'!D66)^1+(1+'1. Configure'!D66)^1*60+32.4*12*(1+'1. Configure'!D66)^1+(1+'1. Configure'!D66)^1*1000)*(1-'1. Configure'!D39) -> 13277.668 | F22: =('1. Configure'!D24*1*12*(1+'1. Configure'!D66)^2+'1. Configure'!D28*0.2*12*(1+'1. Configure'!D66)^2+('1. Configure'!D26/1024)*('1. Configure'!D27/1000)*'1. Configure'!D28*0.0000166667*12*(1+'1. Configure'!D66)^2+'1. Configure'!D29*0.4*12*(1+'1. Configure'!D66)^2+MAX(0,'1. Configure'!D30-1)*1*12*(1+'1. Configure'!D66)^2+'1. Configure'!D31*0.000025*1000000*12*(1+'1. Configure'!D66)^2+'1. Configure'!D32*0.04048*365*(1+'1. Configure'!D66)^2+'1. Configure'!D33*0.04479*365*(1+'1. Configure'!D66)^2+'1. Configure'!D34*0.5*12*(1+'1. Configure'!D66)^2+'1. Configure'!D34*12*0.03*12*(1+'1. Configure'!D66)^2+'1. Configure'!D35*1024*0.09*12*(1+'1. Configure'!D66)^2+5*12*(1+'1. Configure'!D66)^2+(1+'1. Configure'!D66)^2*60+32.4*12*(1+'1. Configure'!D66)^2+(1+'1. Configure'!D66)^2*1000)*(1-'1. Configure'!D39) -> 15269.318 | G22: =('1. Configure'!D24*1*12*(1+'1. Configure'!D66)^3+'1. Configure'!D28*0.2*12*(1+'1. Configure'!D66)^3+('1. Configure'!D26/1024)*('1. Configure'!D27/1000)*'1. Configure'!D28*0.0000166667*12*(1+'1. Configure'!D66)^3+'1. Configure'!D29*0.4*12*(1+'1. Configure'!D66)^3+MAX(0,'1. Configure'!D30-1)*1*12*(1+'1. Configure'!D66)^3+'1. Configure'!D31*0.000025*1000000*12*(1+'1. Configure'!D66)^3+'1. Configure'!D32*0.04048*365*(1+'1. Configure'!D66)^3+'1. Configure'!D33*0.04479*365*(1+'1. Configure'!D66)^3+'1. Configure'!D34*0.5*12*(1+'1. Configure'!D66)^3+'1. Configure'!D34*12*0.03*12*(1+'1. Configure'!D66)^3+'1. Configure'!D35*1024*0.09*12*(1+'1. Configure'!D66)^3+5*12*(1+'1. Configure'!D66)^3+(1+'1. Configure'!D66)^3*60+32.4*12*(1+'1. Configure'!D66)^3+(1+'1. Configure'!D66)^3*1000)*(1-'1. Configure'!D39) -> 17559.716 | H22: =('1. Configure'!D24*1*12*(1+'1. Configure'!D66)^4+'1. Configure'!D28*0.2*12*(1+'1. Configure'!D66)^4+('1. Configure'!D26/1024)*('1. Configure'!D27/1000)*'1. Configure'!D28*0.0000166667*12*(1+'1. Configure'!D66)^4+'1. Configure'!D29*0.4*12*(1+'1. Configure'!D66)^4+MAX(0,'1. Configure'!D30-1)*1*12*(1+'1. Configure'!D66)^4+'1. Configure'!D31*0.000025*1000000*12*(1+'1. Configure'!D66)^4+'1. Configure'!D32*0.04048*365*(1+'1. Configure'!D66)^4+'1. Configure'!D33*0.04479*365*(1+'1. Configure'!D66)^4+'1. Configure'!D34*0.5*12*(1+'1. Configure'!D66)^4+'1. Configure'!D34*12*0.03*12*(1+'1. Configure'!D66)^4+'1. Configure'!D35*1024*0.09*12*(1+'1. Configure'!D66)^4+5*12*(1+'1. Configure'!D66)^4+(1+'1. Configure'!D66)^4*60+32.4*12*(1+'1. Configure'!D66)^4+(1+'1. Configure'!D66)^4*1000)*(1-'1. Configure'!D39) -> 20193.674
B23: AWS — People & Developers | C23: 0 | D23: ='1. Configure'!D36*'1. Configure'!D37*(1+'1. Configure'!D66)^1+'1. Configure'!D38*(1+'1. Configure'!D66)^1 -> 695750 | E23: ='1. Configure'!D36*'1. Configure'!D37*(1+'1. Configure'!D66)^2+'1. Configure'!D38*(1+'1. Configure'!D66)^2 -> 800112.5 | F23: ='1. Configure'!D36*'1. Configure'!D37*(1+'1. Configure'!D66)^3+'1. Configure'!D38*(1+'1. Configure'!D66)^3 -> 920129.38 | G23: ='1. Configure'!D36*'1. Configure'!D37*(1+'1. Configure'!D66)^4+'1. Configure'!D38*(1+'1. Configure'!D66)^4 -> 1058148.8 | H23: ='1. Configure'!D36*'1. Configure'!D37*(1+'1. Configure'!D66)^5+'1. Configure'!D38*(1+'1. Configure'!D66)^5 -> 1216871.1
B24: TOTAL AWS COST | C24: =C22+C23 -> 0 | D24: =D22+D23 -> 707295.8 | E24: =E22+E23 -> 813390.17 | F24: =F22+F23 -> 935398.69 | G24: =G22+G23 -> 1075708.5 | H24: =H22+H23 -> 1237064.8
B26: Annual Savings | C26: =-C44 -> -1864150.7 | D26: =D20-D24 -> 606044.2 | E26: =E20-E24 -> 578750.23 | F26: =F20-F24 -> 540270.13 | G26: =G20-G24 -> 488500.46 | H26: =H20-H24 -> 420996.72
B27: Cumulative Savings | C27: =C26 -> -1864150.7 | D27: =C27+D26 -> -1258106.5 | E27: =D27+E26 -> -679356.31 | F27: =E27+F26 -> -139086.18 | G27: =F27+G26 -> 349414.28 | H27: =G27+H26 -> 770411
B29: ONE-TIME MIGRATION INVESTMENT
B30: Cost Item | C30: Amount (USD)
B31: Discovery & Assessment | C31: ='1. Configure'!D59 -> 50000
B32: Complex Integrations | C32: =ROUND('1. Configure'!D42*'1. Configure'!D43,0)*'1. Configure'!D52 -> 25000
B33: Medium Integrations | C33: =ROUND('1. Configure'!D42*'1. Configure'!D44,0)*'1. Configure'!D53 -> 75000
B34: Simple Integrations | C34: =ROUND('1. Configure'!D42*'1. Configure'!D45,0)*'1. Configure'!D54 -> 16000
B35: DataWeave Transformations | C35: ='1. Configure'!D46*'1. Configure'!D55 -> 60000
B36: External Consulting | C36: ='1. Configure'!D49*'1. Configure'!D56 -> 105000
B37: Testing & QA | C37: =(C32+C33+C34+C35+C36)*'1. Configure'!D57 -> 84300
B38: Parallel Run (dual systems) | C38: ='1. Configure'!D48*(D20/12+D24/12) -> 505158.95
B39: Internal Team (dedicated) | C39: ='1. Configure'!D47*('1. Configure'!D18*'1. Configure'!D19/12) -> 600000
B40: AWS Training | C40: ='1. Configure'!D36*'1. Configure'!D61 -> 8000
B41: Temporary Tools & Licenses | C41: ='1. Configure'!D60 -> 25000
B42: Risk & Contingency | C42: =SUM(C31:C41)*'1. Configure'!D58 -> 310691.79
B44: TOTAL MIGRATION INVESTMENT | C44: =SUM(C31:C42) -> 1864150.7
B46: RETURN ON INVESTMENT ANALYSIS
B47: Metric | C47: Value | D47: Interpretation
B48: Total Migration Investment | C48: =C44 -> 1864150.7 | D48: Upfront capital required to execute the migration.
B49: Year 1 Annual Savings | C49: =D26 -> 606044.2 | D49: Immediate reduction in recurring platform and people costs.
B50: Year 1 Savings Rate | C50: =IF(D20>0,D26/D20,0) -> 0.46145263 | D50: Share of MuleSoft cost eliminated. >30% is strong.
...
